#VRML_SIM R2025a utf8

EXTERNPROTO "https://raw.githubusercontent.com/cyberbotics/webots/R2025a/projects/objects/backgrounds/protos/TexturedBackground.proto"
EXTERNPROTO "https://raw.githubusercontent.com/cyberbotics/webots/R2025a/projects/objects/backgrounds/protos/TexturedBackgroundLight.proto"
EXTERNPROTO "https://raw.githubusercontent.com/cyberbotics/webots/R2025a/projects/objects/floors/protos/Floor.proto"

WorldInfo {
  title "Inclined Plane"
  basicTimeStep 16
  randomSeed 42
}
Viewpoint {
  fieldOfView 1
  orientation -0.24291848019114168 -0.28533034614898084 0.9271338660345273 4.797550243202629
  position -0.8979374435369719 2.631959165690893 1.2627424650717858
}
TexturedBackground {
  texture "mars"
}
TexturedBackgroundLight {
  texture "mars"
}
Floor {
  size 5 5
  tileSize 1 1
}
Solid {
  translation -1 -1.7925783587254483e-11 0.09960760000118135
  rotation -0.9999999999999994 5.950989179810667e-09 3.4968623480589424e-08 2.7760358689543278e-09
  children [
    Shape {
      appearance PBRAppearance {
        baseColor 0 0 1
      }
      geometry Box {
        size 0.2 0.2 0.2
      }
    }
  ]
  name "box1"
  boundingObject Box {
    size 0.2 0.2 0.2
  }
  physics Physics {
    mass 1
  }
  linearVelocity -1.625325055793203e-17 -4.3225947406751263e-10 -1.62932565217102e-11
  angularVelocity 4.323658231340258e-09 1.332267629550195e-16 -1.5946019170391512e-16
}
Solid {
  translation -1 1.2506203394423562e-07 0.2994767999711868
  rotation -0.9999999999999186 3.0536384283097614e-08 -4.0194511580372244e-07 9.070551769892197e-10
  children [
    Shape {
      appearance PBRAppearance {
        baseColor 0 1 0
      }
      geometry Box {
        size 0.2 0.2 0.2
      }
    }
  ]
  name "box2"
  boundingObject Box {
    size 0.2 0.2 0.2
  }
  physics Physics {
    mass 1
  }
  linearVelocity -1.615441464301063e-17 2.9270314016589777e-09 4.538554207938371e-10
  angularVelocity -3.790963946667266e-08 2.6645352591003943e-16 -2.3994022699602346e-16
}
Robot {
  translation 0 0 0.09
  children [
    Solid {
      translation 0 0 -0.0001177198924778855
      children [
        Shape {
          appearance PBRAppearance {
            baseColor 0 0 1
          }
          geometry Box {
            size 0.2 0.2 0.2
          }
        }
      ]
      name "solid_base"
      boundingObject Box {
        size 0.2 0.2 0.2
      }
      physics Physics {
        mass 1
      }
      linearVelocity 0 0 -1.2002601576363908e-10
    }
    HingeJoint {
      jointParameters HingeJointParameters {
        position 8.031324985418797
        axis 0 1 0
        anchor 0 0.2 0
      }
      device [
        RotationalMotor {
          name "motor"
        }
      ]
      endPoint Solid {
        translation 0.19685513176562316 -3.139199397650394e-07 -0.03528161559606006
        rotation -1.312688907628188e-06 -0.9999999999979078 1.5688859775025376e-06 4.535045755020743
        children [
          Shape {
            appearance PBRAppearance {
              baseColor 0 1 0
            }
            geometry Box {
              size 0.2 0.2 0.2
            }
          }
        ]
        name "solid_box"
        boundingObject Box {
          size 0.2 0.2 0.2
        }
        physics Physics {
          mass 1
        }
        linearVelocity -0.06426655551531817 6.211805671722736e-07 -0.3957566162823435
        angularVelocity 2.3745946710416465e-12 2.000019411753447 3.1392350487024013e-06
      }
    }
  ]
  controller "test_py_controller"
}
