#VRML_SIM R2025a utf8

EXTERNPROTO "https://raw.githubusercontent.com/cyberbotics/webots/R2025a/projects/objects/backgrounds/protos/TexturedBackground.proto"
EXTERNPROTO "https://raw.githubusercontent.com/cyberbotics/webots/R2025a/projects/objects/backgrounds/protos/TexturedBackgroundLight.proto"
EXTERNPROTO "https://raw.githubusercontent.com/cyberbotics/webots/R2025a/projects/objects/floors/protos/Floor.proto"

WorldInfo {
  title "Inclined Plane"
  basicTimeStep 16
  randomSeed 42
}
Viewpoint {
  fieldOfView 1
  orientation -0.24291848019114168 -0.28533034614898084 0.9271338660345273 4.797550243202629
  position -0.8979374435369719 2.631959165690893 1.2627424650717858
}
TexturedBackground {
  texture "mars"
}
TexturedBackgroundLight {
  texture "mars"
}
Floor {
  size 5 5
  tileSize 1 1
}
Solid {
  translation -1 -3.5114953298539888e-09 0.09960760032678641
  rotation 1 -8.144667450434359e-11 3.110855949836355e-09 3.271478270616403e-08
  children [
    Shape {
      appearance PBRAppearance {
        baseColor 0 0 1
      }
      geometry Box {
        size 0.2 0.2 0.2
      }
    }
  ]
  name "box1"
  boundingObject Box {
    size 0.2 0.2 0.2
  }
  physics Physics {
    mass 1
  }
  linearVelocity -1.839978246877967e-17 -3.107007348253435e-07 6.420499175874528e-09
  angularVelocity 3.097676905916356e-06 -1.3322676295502073e-16 -4.5587471338092496e-17
}
Solid {
  translation -1 1.4537950467550805e-06 0.29947665259219053
  rotation -1 7.991428165221144e-13 -2.7125952132929308e-11 1.331694929501839e-05
  children [
    Shape {
      appearance PBRAppearance {
        baseColor 0 1 0
      }
      geometry Box {
        size 0.2 0.2 0.2
      }
    }
  ]
  name "box2"
  boundingObject Box {
    size 0.2 0.2 0.2
  }
  physics Physics {
    mass 1
  }
  linearVelocity -1.0684673561465589e-16 -2.1891729601272218e-05 2.322625039653299e-06
  angularVelocity 0.00021298867750111017 -1.9984014443252545e-16 -1.429614384733558e-16
}
Robot {
  translation 0 0 0.09
  children [
    Solid {
      translation 0 0 -0.00012556788479772818
      children [
        Shape {
          appearance PBRAppearance {
            baseColor 0 0 1
          }
          geometry Box {
            size 0.2 0.2 0.2
          }
        }
      ]
      name "solid_base"
      boundingObject Box {
        size 0.2 0.2 0.2
      }
      physics Physics {
        mass 1
      }
      linearVelocity 0 0 -1.2002601576363908e-10
    }
    HingeJoint {
      jointParameters HingeJointParameters {
        position 131.06081854953356
        axis 0 1 0
        anchor 0 0.2 0
      }
      device [
        RotationalMotor {
          name "motor"
        }
      ]
      endPoint Solid {
        translation -0.15491246990248886 -3.139199396817727e-07 0.12648660786913174
        rotation -3.3061281034782797e-06 0.9999999999933044 -1.5687265513868315e-06 5.397112279865579
        children [
          Shape {
            appearance PBRAppearance {
              baseColor 0 1 0
            }
            geometry Box {
              size 0.2 0.2 0.2
            }
          }
        ]
        name "solid_box"
        boundingObject Box {
          size 0.2 0.2 0.2
        }
        physics Physics {
          mass 1
        }
        linearVelocity 0.24845980942168736 -4.939022343693723e-07 0.31466737715618875
        angularVelocity 6.820938181782283e-13 1.9999844133114948 3.1391770167468366e-06
      }
    }
  ]
  controller "test_py_controller"
}
