#VRML_SIM R2025a utf8

EXTERNPROTO "https://raw.githubusercontent.com/cyberbotics/webots/R2025a/projects/objects/backgrounds/protos/TexturedBackground.proto"
EXTERNPROTO "https://raw.githubusercontent.com/cyberbotics/webots/R2025a/projects/objects/backgrounds/protos/TexturedBackgroundLight.proto"
EXTERNPROTO "https://raw.githubusercontent.com/cyberbotics/webots/R2025a/projects/objects/floors/protos/Floor.proto"

WorldInfo {
  title "Inclined Plane"
  basicTimeStep 16
  randomSeed 42
}
Viewpoint {
  fieldOfView 1
  orientation -0.24291848019114168 -0.28533034614898084 0.9271338660345273 4.797550243202629
  position -1.3107215140315986 6.869383258888592 3.596750955786373
}
TexturedBackground {
  texture "mars"
}
TexturedBackgroundLight {
  texture "mars"
}
Floor {
  size 5 5
  tileSize 1 1
}
Solid {
  translation -0.8 1.3462380734167132e-05 0.2994767999533072
  rotation -1 -1.6624066203424952e-11 2.4308524672572323e-10 4.8434074883452e-07
  children [
    Shape {
      appearance PBRAppearance {
        baseColor 0 0 1
      }
      geometry Box {
        size 0.2 0.2 0.2
      }
    }
  ]
  name "box1"
  boundingObject Box {
    size 0.2 0.2 0.2
  }
  physics Physics {
    mass 1
  }
  linearVelocity 1.4281004029313454e-16 -4.0530329369035645e-10 6.3898749820755e-10
  angularVelocity 6.700272683638986e-09 1.3322676295501846e-16 7.939670430236559e-17
}
Solid {
  translation -0.8 -1.302681906434959e-06 0.09960760000274488
  rotation -1 1.461255353137075e-11 -1.2408683750492867e-09 2.9074122311051325e-07
  children [
    Shape {
      appearance PBRAppearance {
        baseColor 0 1 0
      }
      geometry Box {
        size 0.2 0.2 0.2
      }
    }
  ]
  name "box2"
  boundingObject Box {
    size 0.2 0.2 0.2
  }
  physics Physics {
    mass 1
  }
  linearVelocity 4.259816433078091e-17 1.279503540376172e-10 -3.904284540112713e-11
  angularVelocity -1.2798806015013042e-09 1.3322676295501878e-16 -1.074522629034501e-17
}
Robot {
  translation 0 0 0.09
  children [
    Solid {
      translation 0 0 -0.00013341587711757086
      children [
        Shape {
          appearance PBRAppearance {
            baseColor 0 0 1
          }
          geometry Box {
            size 0.2 0.2 0.2
          }
        }
      ]
      name "solid_base"
      boundingObject Box {
        size 0.2 0.2 0.2
      }
      physics Physics {
        mass 1
      }
      linearVelocity 0 0 -1.2002601576363908e-10
    }
    HingeJoint {
      jointParameters HingeJointParameters {
        position 206.38111776780778
        axis 0 1 0
        anchor 0 0.2 0
      }
      device [
        RotationalMotor {
          name "motor"
        }
      ]
      endPoint Solid {
        translation -0.16428880593918058 -3.139199397372838e-07 0.11404351601299956
        rotation -2.9986252973167447e-06 0.9999999999942736 -1.5687277575644224e-06 5.3191878119852385
        children [
          Shape {
            appearance PBRAppearance {
              baseColor 0 1 0
            }
            geometry Box {
              size 0.2 0.2 0.2
            }
          }
        ]
        name "solid_box"
        boundingObject Box {
          size 0.2 0.2 0.2
        }
        physics Physics {
          mass 1
        }
        linearVelocity 0.9925240834279303 -2.8665352387462137e-06 1.8262822471219111
        angularVelocity 2.1375793909611477e-11 9.999981101652219 1.56959764249537e-05
      }
    }
  ]
  controller "test_py_controller"
}
