#VRML_SIM R2025a utf8

EXTERNPROTO "https://raw.githubusercontent.com/cyberbotics/webots/R2025a/projects/objects/backgrounds/protos/TexturedBackground.proto"
EXTERNPROTO "https://raw.githubusercontent.com/cyberbotics/webots/R2025a/projects/objects/backgrounds/protos/TexturedBackgroundLight.proto"
EXTERNPROTO "https://raw.githubusercontent.com/cyberbotics/webots/R2025a/projects/objects/floors/protos/Floor.proto"

WorldInfo {
  title "Inclined Plane"
  basicTimeStep 16
  randomSeed 42
}
Viewpoint {
  fieldOfView 1
  orientation -0.24291848019114168 -0.28533034614898084 0.9271338660345273 4.797550243202629
  position -0.8979374435369719 2.631959165690893 1.2627424650717858
}
TexturedBackground {
  texture "mars"
}
TexturedBackgroundLight {
  texture "mars"
}
Floor {
  size 5 5
  tileSize 1 1
}
Solid {
  translation -1 -7.319551365644612e-10 0.09960760002687223
  rotation 0.9999999999999996 -1.0372420829399065e-08 2.1593037784186503e-08 4.36706734536375e-09
  children [
    Shape {
      appearance PBRAppearance {
        baseColor 0 0 1
      }
      geometry Box {
        size 0.2 0.2 0.2
      }
    }
  ]
  name "box1"
  boundingObject Box {
    size 0.2 0.2 0.2
  }
  physics Physics {
    mass 1
  }
  linearVelocity -4.51844602020796e-17 8.518663560954422e-09 -3.403858386262588e-10
  angularVelocity -8.523314680723871e-08 1.332267629550205e-16 -1.0128869316318565e-16
}
Solid {
  translation -1 1.2676757609442592e-07 0.29947679895861246
  rotation -1 3.1128523282960664e-10 -3.8149528012394e-09 8.898741740415098e-08
  children [
    Shape {
      appearance PBRAppearance {
        baseColor 0 1 0
      }
      geometry Box {
        size 0.2 0.2 0.2
      }
    }
  ]
  name "box2"
  boundingObject Box {
    size 0.2 0.2 0.2
  }
  physics Physics {
    mass 1
  }
  linearVelocity 1.537982400768389e-17 -1.1841598253819237e-07 1.6405019607638196e-08
  angularVelocity 1.3563391545554512e-06 3.330669073875489e-16 -2.6027974164727174e-18
}
Robot {
  translation 0 0 0.09
  children [
    Solid {
      translation 0 0 -0.00010202390783820015
      children [
        Shape {
          appearance PBRAppearance {
            baseColor 0 0 1
          }
          geometry Box {
            size 0.2 0.2 0.2
          }
        }
      ]
      name "solid_base"
      boundingObject Box {
        size 0.2 0.2 0.2
      }
      physics Physics {
        mass 1
      }
      linearVelocity 0 0 -1.2002601576363908e-10
    }
    HingeJoint {
      jointParameters HingeJointParameters {
        position -1.6085445796595705e-06
        axis 0 1 0
        anchor 0 0.2 0
      }
      device [
        RotationalMotor {
          name "motor"
        }
      ]
      endPoint Solid {
        translation -3.095840418198446e-07 -3.13919939792795e-07 0.19999183808704066
        rotation 0.8751892029005888 -0.48378079655881573 -2.673873465375682e-06 3.585579817151301e-06
        children [
          Shape {
            appearance PBRAppearance {
              baseColor 0 1 0
            }
            geometry Box {
              size 0.2 0.2 0.2
            }
          }
        ]
        name "solid_box"
        boundingObject Box {
          size 0.2 0.2 0.2
        }
        physics Physics {
          mass 1
        }
        linearVelocity -3.1434264433129217e-06 -4.790532199120481e-12 -1.2475220499615592e-10
        angularVelocity 2.4001480308258267e-11 -1.5740484641883762e-05 8.487510831377077e-10
      }
    }
  ]
  controller "<none>"
}
